ansible-playbook 2.6.3
  config file = /home/chris/MyDocuments/RedHat/Projects/ansible-examples/jboss-standalone/ansible.cfg
  configured module search path = [u'/home/chris/.ansible/plugins/modules', u'/usr/share/ansible/plugins/modules']
  ansible python module location = /usr/lib/python2.7/site-packages/ansible
  executable location = /usr/bin/ansible-playbook
  python version = 2.7.15 (default, May 16 2018, 17:50:09) [GCC 8.1.1 20180502 (Red Hat 8.1.1-1)]
Using /home/chris/MyDocuments/RedHat/Projects/ansible-examples/jboss-standalone/ansible.cfg as config file

PLAYBOOK: regression-test.yml **************************************************
1 plays in regression-test.yml

PLAY [all] *********************************************************************

TASK [Gathering Facts] *********************************************************
task path: /home/chris/MyDocuments/RedHat/Projects/ansible-examples/jboss-standalone/regression-test.yml:5
ok: [52.53.242.30]
ok: [52.53.248.131]
ok: [54.183.160.110]
META: ran handlers

TASK [regression-test : Ticket Monster - Test 3] *******************************
task path: /home/chris/MyDocuments/RedHat/Projects/ansible-examples/jboss-standalone/roles/regression-test/tasks/main.yml:66
An exception occurred during task execution. To see the full traceback, use -vvv. The error was: AttributeError: 'NoneType' object has no attribute 'find'
fatal: [52.53.242.30]: FAILED! => {"changed": false, "content": "", "msg": "Status code was -1 and not [200]: An unknown error occurred: 'NoneType' object has no attribute 'find'", "redirected": false, "status": -1, "url": null}
...ignoring
An exception occurred during task execution. To see the full traceback, use -vvv. The error was: AttributeError: 'NoneType' object has no attribute 'find'
fatal: [54.183.160.110]: FAILED! => {"changed": false, "content": "", "msg": "Status code was -1 and not [200]: An unknown error occurred: 'NoneType' object has no attribute 'find'", "redirected": false, "status": -1, "url": null}
...ignoring
An exception occurred during task execution. To see the full traceback, use -vvv. The error was: AttributeError: 'NoneType' object has no attribute 'find'
fatal: [52.53.248.131]: FAILED! => {"changed": false, "content": "", "msg": "Status code was -1 and not [200]: An unknown error occurred: 'NoneType' object has no attribute 'find'", "redirected": false, "status": -1, "url": null}
...ignoring

TASK [regression-test : Ticket Monster - Validation 3] *************************
task path: /home/chris/MyDocuments/RedHat/Projects/ansible-examples/jboss-standalone/roles/regression-test/tasks/main.yml:74
fatal: [54.183.160.110]: FAILED! => {"changed": false, "msg": "Failed as requested from task"}
fatal: [52.53.242.30]: FAILED! => {"changed": false, "msg": "Failed as requested from task"}
fatal: [52.53.248.131]: FAILED! => {"changed": false, "msg": "Failed as requested from task"}

PLAY RECAP *********************************************************************
52.53.242.30               : ok=2    changed=0    unreachable=0    failed=1   
52.53.248.131              : ok=2    changed=0    unreachable=0    failed=1   
54.183.160.110             : ok=2    changed=0    unreachable=0    failed=1   

